Workbook
Name auxtable: Pesos!$L$17:$M$36
Name MASTERTABLE: Pesos!$B$17:$I$40

Sheet ORDEN DE COMPRA
C1: ORDEN DE COMPRA | G1: CARGA | H1: 46195 | L1: ORDEN DE COMPRA | P1: CARGA | Q1: =H1 -> 46195
G2: OC.696/E640 | P2: =G2 -> OC.696/E640
G3: FECHA: | H3: =NOW() -> 46206.632 | P3: FECHA: | Q3: =NOW() -> 46206.632
C4: ELSY GUADALUPE SOSA CHAVEZ | G4: E-NN ENTRADA ELY DIRECTO D | L4: ALVARO RESENDIZ GALLEGOS
C5: =VLOOKUP($C$4,CONCEPTOS!$I$1:$L$15,2,0) -> AIDC780612P9A | L5: =VLOOKUP($L$4,CONCEPTOS!$I$18:$L$32,2,0) -> REGA5602198E6
C6: =VLOOKUP($C$4,CONCEPTOS!$I$1:$L$15,3,0) -> CALLE 6 No.370 COL.SAN MARCOS NOCOH, MERIDA, YUCATAN C.P.97296 | D6: =VLOOKUP(D5,CONCEPTOS!$I$1:$L$15,2,0) -> #N/A | E6: =VLOOKUP(E5,CONCEPTOS!$I$1:$L$15,2,0) -> #N/A | F6: =VLOOKUP(F5,CONCEPTOS!$I$1:$L$15,2,0) -> #N/A | G6: =VLOOKUP(G5,CONCEPTOS!$I$1:$L$15,2,0) -> #N/A | L6: =VLOOKUP($L$4,CONCEPTOS!$I$18:$L$32,3,0) -> CALLE 22 No109A ENTRE 23 Y 25 CHOLUL, MERIDA, YUCATAN, MEXICO | M6: =VLOOKUP(M5,CONCEPTOS!$I$1:$L$15,2,0) -> #N/A | N6: =VLOOKUP(N5,CONCEPTOS!$I$1:$L$15,2,0) -> #N/A | O6: =VLOOKUP(O5,CONCEPTOS!$I$1:$L$15,2,0) -> #N/A | P6: =VLOOKUP(P5,CONCEPTOS!$I$1:$L$15,2,0) -> #N/A
C7: =VLOOKUP($C$4,CONCEPTOS!$I$1:$L$15,4,0) -> P.F. ACT EMP Y PROF | D7: =VLOOKUP(D6,CONCEPTOS!$I$1:$L$15,2,0) -> #N/A | E7: =VLOOKUP(E6,CONCEPTOS!$I$1:$L$15,2,0) -> #N/A | F7: =VLOOKUP(F6,CONCEPTOS!$I$1:$L$15,2,0) -> #N/A | G7: =VLOOKUP(G6,CONCEPTOS!$I$1:$L$15,2,0) -> #N/A | L7: =VLOOKUP($L$4,CONCEPTOS!$I$18:$L$32,4,0) -> P.F. ACT EMP Y PROF | M7: =VLOOKUP(M6,CONCEPTOS!$I$1:$L$15,2,0) -> #N/A | N7: =VLOOKUP(N6,CONCEPTOS!$I$1:$L$15,2,0) -> #N/A | O7: =VLOOKUP(O6,CONCEPTOS!$I$1:$L$15,2,0) -> #N/A | P7: =VLOOKUP(P6,CONCEPTOS!$I$1:$L$15,2,0) -> #N/A
H9: EMITIDO PARA: | Q9: EMITIDO PARA:
F10: RAZON SOCIAL: | G10: CELESTE DE LA CRUZ ROJAS RAMIREZ | O10: RAZON SOCIAL: | P10: =C4 -> ELSY GUADALUPE SOSA CHAVEZ
G11: PROVEEDOR : | H11: RODRIGO CALDERA
C16: METODO DE PAGO: | E16: PPD | L16: METODO DE PAGO: | N16: PPD
C17: FORMA DE PAGO: | E17: 99-POR DEFINIR | J17: RETENCION | L17: FORMA DE PAGO: | N17: 99-POR DEFINIR
C18: CONDICIONES DE PAGO: | J18: NO | L18: CONDICIONES DE PAGO:
C20: CLAVE SAT | D20: CANTIDAD | E20: UNIDAD | F20: DESCRIPCION | G20: PRECIO UNITARIO | H20: TOTAL | J20: PRECIO NETO | L20: CLAVE SAT | M20: CANTIDAD | N20: UNIDAD | O20: DESCRIPCION | P20: PRECIO UNITARIO | Q20: TOTAL | S20: MARGEN
C21: =VLOOKUP(F21,CONCEPTOS!$A$1:$C$54,3,0) -> 11191610 | D21: 7485 | E21: KGM | F21: ALUMINIO 1100 TRASTE | G21: =IF(J21="","",IF($J$18="NO",ROUND(J21/1.16,6),J21)) -> 37.068966 | H21: =IF(D21="","",D21*G21) -> 277461.21 | J21: 43 | L21: =IF(C21="","",C21) -> 11191610 | M21: =IF(D21="","",D21) -> 7485 | N21: =IF(E21="","",E21) -> KGM | O21: =IF(F21="","",F21) -> ALUMINIO 1100 TRASTE | P21: =IF(G21="","",G21+$S$21) -> 37.098966 | Q21: =IF(M21="","",M21*P21) -> 277685.76 | S21: 0.03
C22: =IFERROR(VLOOKUP(F22,CONCEPTOS!$A$1:$C$54,3,0),"") -> 11191610 | D22: 1638 | E22: KGM | F22: ALUMINIO CABLE | G22: =IF(J22="","",IF($J$18="NO",ROUND(J22/1.16,6),J22)) -> 62.931034 | H22: =IF(D22="","",D22*G22) -> 103081.03 | J22: 73 | L22: =IF(C22="","",C22) -> 11191610 | M22: =IF(D22="","",D22) -> 1638 | N22: =IF(E22="","",E22) -> KGM | O22: =IF(F22="","",F22) -> ALUMINIO CABLE | P22: =IF(G22="","",G22+$S$21) -> 62.961034 | Q22: =IF(M22="","",M22*P22) -> 103130.17
C23: =IFERROR(VLOOKUP(F23,CONCEPTOS!$A$1:$C$54,3,0),"") -> 11191610 | D23: 4683 | E23: KGM | F23: ALUMINIO RIN CHICO | G23: =IF(J23="","",IF($J$18="NO",ROUND(J23/1.16,6),J23)) -> 59.913793 | H23: =IF(D23="","",D23*G23) -> 280576.29 | J23: 69.5 | L23: =IF(C23="","",C23) -> 11191610 | M23: =IF(D23="","",D23) -> 4683 | N23: =IF(E23="","",E23) -> KGM | O23: =IF(F23="","",F23) -> ALUMINIO RIN CHICO | P23: =IF(G23="","",G23+$S$21) -> 59.943793 | Q23: =IF(M23="","",M23*P23) -> 280716.78
C24: =IFERROR(VLOOKUP(F24,CONCEPTOS!$A$1:$C$54,3,0),"") -> 11191610 | D24: 5924 | E24: KGM | F24: ALUMINIO MACIZO | G24: =IF(J24="","",IF($J$18="NO",ROUND(J24/1.16,6),J24)) -> 38.362069 | H24: =IF(D24="","",D24*G24) -> 227256.9 | J24: 44.5 | L24: =IF(C24="","",C24) -> 11191610 | M24: =IF(D24="","",D24) -> 5924 | N24: =IF(E24="","",E24) -> KGM | O24: =IF(F24="","",F24) -> ALUMINIO MACIZO | P24: =IF(G24="","",G24+$S$21) -> 38.392069 | Q24: =IF(M24="","",M24*P24) -> 227434.62
C25: =IFERROR(VLOOKUP(F25,CONCEPTOS!$A$1:$C$54,3,0),"") -> 11191610 | D25: 1830 | E25: KGM | F25: ANTIMONIO | G25: =IF(J25="","",IF($J$18="NO",ROUND(J25/1.16,6),J25)) -> 35.344828 | H25: =IF(D25="","",D25*G25) -> 64681.035 | J25: 41 | L25: =IF(C25="","",C25) -> 11191610 | M25: =IF(D25="","",D25) -> 1830 | N25: =IF(E25="","",E25) -> KGM | O25: =IF(F25="","",F25) -> ANTIMONIO | P25: =IF(G25="","",G25+$S$21) -> 35.374828 | Q25: =IF(M25="","",M25*P25) -> 64735.935
C26: =IFERROR(VLOOKUP(F26,CONCEPTOS!$A$1:$C$54,3,0),"") | G26: =IF(J26="","",IF($J$18="NO",ROUND(J26/1.16,6),J26)) | H26: =IF(D26="","",D26*G26) | L26: =IF(C26="","",C26) | M26: =IF(D26="","",D26) | N26: =IF(E26="","",E26) | O26: =IF(F26="","",F26) | P26: =IF(G26="","",G26+$S$21) | Q26: =IF(M26="","",M26*P26)
C27: =IFERROR(VLOOKUP(F27,CONCEPTOS!$A$1:$C$54,3,0),"") | G27: =IF(J27="","",IF($J$18="NO",ROUND(J27/1.16,6),J27)) | H27: =IF(D27="","",D27*G27) | L27: =IF(C27="","",C27) | M27: =IF(D27="","",D27) | N27: =IF(E27="","",E27) | O27: =IF(F27="","",F27) | P27: =IF(G27="","",G27+$S$21) | Q27: =IF(M27="","",M27*P27)
C28: =IFERROR(VLOOKUP(F28,CONCEPTOS!$A$1:$C$54,3,0),"") | G28: =IF(J28="","",IF($J$18="NO",ROUND(J28/1.16,6),J28)) | H28: =IF(D28="","",D28*G28) | L28: =IF(C28="","",C28) | M28: =IF(D28="","",D28) | N28: =IF(E28="","",E28) | O28: =IF(F28="","",F28) | P28: =IF(G28="","",G28+$S$21) | Q28: =IF(M28="","",M28*P28)
C29: =IFERROR(VLOOKUP(F29,CONCEPTOS!$A$1:$C$54,3,0),"") | G29: =IF(J29="","",IF($J$18="NO",ROUND(J29/1.16,6),J29)) | H29: =IF(D29="","",D29*G29) | L29: =IF(C29="","",C29) | M29: =IF(D29="","",D29) | N29: =IF(E29="","",E29) | O29: =IF(F29="","",F29) | P29: =IF(G29="","",G29+$S$21) | Q29: =IF(M29="","",M29*P29)
C30: =IFERROR(VLOOKUP(F30,CONCEPTOS!$A$1:$C$54,3,0),"") | G30: =IF(J30="","",IF($J$18="NO",ROUND(J30/1.16,6),J30)) | H30: =IF(D30="","",D30*G30) | L30: =IF(C30="","",C30) | M30: =IF(D30="","",D30) | N30: =IF(E30="","",E30) | O30: =IF(F30="","",F30) | P30: =IF(G30="","",G30+$S$21) | Q30: =IF(M30="","",M30*P30)
C31: =IFERROR(VLOOKUP(F31,CONCEPTOS!$A$1:$C$54,3,0),"") | G31: =IF(J31="","",IF($J$18="NO",ROUND(J31/1.16,6),J31)) | H31: =IF(D31="","",D31*G31) | L31: =IF(C31="","",C31) | M31: =IF(D31="","",D31) | N31: =IF(E31="","",E31) | O31: =IF(F31="","",F31) | P31: =IF(G31="","",G31+$S$21) | Q31: =IF(M31="","",M31*P31)
C32: =IFERROR(VLOOKUP(F32,CONCEPTOS!$A$1:$C$54,3,0),"") | G32: =IF(J32="","",IF($J$18="NO",ROUND(J32/1.16,6),J32)) | H32: =IF(D32="","",D32*G32) | L32: =IF(C32="","",C32) | M32: =IF(D32="","",D32) | N32: =IF(E32="","",E32) | O32: =IF(F32="","",F32) | P32: =IF(G32="","",G32+$S$21) | Q32: =IF(M32="","",M32*P32)
C33: =IFERROR(VLOOKUP(F33,CONCEPTOS!$A$1:$C$54,3,0),"") | G33: =IF(J33="","",IF($J$18="NO",ROUND(J33/1.16,6),J33)) | H33: =IF(D33="","",D33*G33) | L33: =IF(C33="","",C33) | M33: =IF(D33="","",D33) | N33: =IF(E33="","",E33) | O33: =IF(F33="","",F33) | P33: =IF(G33="","",G33+$S$21) | Q33: =IF(M33="","",M33*P33)
C34: =IFERROR(VLOOKUP(F34,CONCEPTOS!$A$1:$C$54,3,0),"") | G34: =IF(J34="","",IF($J$18="NO",ROUND(J34/1.16,6),J34)) | H34: =IF(D34="","",D34*G34) | L34: =IF(C34="","",C34) | M34: =IF(D34="","",D34) | N34: =IF(E34="","",E34) | O34: =IF(F34="","",F34) | P34: =IF(G34="","",G34+$S$21) | Q34: =IF(M34="","",M34*P34)
C35: TOTAL | D35: =SUM(D21:D33) -> 21560 | E35: KGM | G35: SUBTOTAL | H35: =SUM(H21:H32) -> 953056.47 | L35: TOTAL | M35: =SUM(M21:M33) -> 21560 | N35: KGM | P35: SUBTOTAL | Q35: =SUM(Q21:Q32) -> 953703.27
G36: IVA 16% | H36: =H35*0.16 -> 152489.04 | P36: IVA 16% | Q36: =Q35*0.16 -> 152592.52
G37: IVA RET. | H37: =IF($J$18="NO",0,H36) -> 0 | P37: IVA RET. | Q37: =IF($J$18="NO",0,Q36) -> 0
G38: TOTAL | H38: =H35+H36-H37 -> 1105545.5 | P38: TOTAL | Q38: =Q35+Q36-Q37 -> 1106295.8 | S38: =Q38-H38 -> 750.288
C39: IMPORTE EN LETRAS SON: | L39: IMPORTE EN LETRAS SON:
C40: {=[1]!cMoneda2(H38,"PESO","PESOS",,"M.N.")} -> #NAME? | L40: {=[1]!cMoneda2(Q38,"PESO","PESOS",,"M.N.")} -> #NAME?
C42: =C4 -> ELSY GUADALUPE SOSA CHAVEZ | G42: =G10 -> CELESTE DE LA CRUZ ROJAS RAMIREZ | L42: =L4 -> ALVARO RESENDIZ GALLEGOS | P42: =P10 -> ELSY GUADALUPE SOSA CHAVEZ
C45: ___________________________ | G45: ___________________________ | L45: ___________________________ | P45: ___________________________
C46: FIRMA COMPRADOR | G46: FIRMA VENDEDOR | L46: FIRMA COMPRADOR | P46: FIRMA VENDEDOR
C48: PAGO: | D48: CONTRA RECEPCIÓN DE DOCUMENTOS | L48: PAGO: | M48: CONTRA RECEPCIÓN DE DOCUMENTOS
D49: *FACTURA COMERCIAL. | M49: *FACTURA COMERCIAL.
D50: *TICKETS DE PESO | M50: *TICKETS DE PESO
...

Sheet OC
C1: ORDEN DE COMPRA | G1: ='ORDEN DE COMPRA'!G1 -> CARGA | H1: ='ORDEN DE COMPRA'!H1 -> 46195
G2: ='ORDEN DE COMPRA'!G2 -> OC.696/E640
G3: FECHA: | H3: =NOW() -> 46206.632
H4: EMITIDO PARA:
G5: ='ORDEN DE COMPRA'!H11 -> RODRIGO CALDERA
L6: PROVEEDOR
C11: METODO DE PAGO: | E11: PPD
C12: FORMA DE PAGO: | E12: 99-POR DEFINIR
C13: CONDICIONES DE PAGO:
M14: =M15/1.16 -> 137014.51
C15: CLAVE SAT | D15: CANTIDAD | E15: UNIDAD | F15: DESCRIPCION | G15: PRECIO UNITARIO | H15: TOTAL | L15: MONEX | M15: 158936.83
C16: ='ORDEN DE COMPRA'!C21 -> 11191610 | D16: =IF('ORDEN DE COMPRA'!D21="","",'ORDEN DE COMPRA'!D21) -> 7485 | E16: =IF('ORDEN DE COMPRA'!E21="","",'ORDEN DE COMPRA'!E21) -> KGM | F16: =IF('ORDEN DE COMPRA'!F21="","",'ORDEN DE COMPRA'!F21) -> ALUMINIO 1100 TRASTE | G16: =IF('ORDEN DE COMPRA'!J21="","",'ORDEN DE COMPRA'!J21) -> 43 | H16: =D16*G16 -> 321855 | M16: =M15/20.9 -> 7604.633
C17: ='ORDEN DE COMPRA'!C22 -> 11191610 | D17: =IF('ORDEN DE COMPRA'!D22="","",'ORDEN DE COMPRA'!D22) -> 1638 | E17: =IF('ORDEN DE COMPRA'!E22="","",'ORDEN DE COMPRA'!E22) -> KGM | F17: =IF('ORDEN DE COMPRA'!F22="","",'ORDEN DE COMPRA'!F22) -> ALUMINIO CABLE | G17: =IF('ORDEN DE COMPRA'!J22="","",'ORDEN DE COMPRA'!J22) -> 73 | H17: =D17*G17 -> 119574 | W17: *EN LAS ORDENES DE COMPRA SIEMPRE SERAN 1.00 ABAJO DEL PRECIO DE LA FACTURA ORIGINAL
C18: ='ORDEN DE COMPRA'!C23 -> 11191610 | D18: =IF('ORDEN DE COMPRA'!D23="","",'ORDEN DE COMPRA'!D23) -> 4683 | E18: =IF('ORDEN DE COMPRA'!E23="","",'ORDEN DE COMPRA'!E23) -> KGM | F18: =IF('ORDEN DE COMPRA'!F23="","",'ORDEN DE COMPRA'!F23) -> ALUMINIO RIN CHICO | G18: =IF('ORDEN DE COMPRA'!J23="","",'ORDEN DE COMPRA'!J23) -> 69.5 | H18: =D18*G18 -> 325468.5
C19: ='ORDEN DE COMPRA'!C24 -> 11191610 | D19: =IF('ORDEN DE COMPRA'!D24="","",'ORDEN DE COMPRA'!D24) -> 5924 | E19: =IF('ORDEN DE COMPRA'!E24="","",'ORDEN DE COMPRA'!E24) -> KGM | F19: =IF('ORDEN DE COMPRA'!F24="","",'ORDEN DE COMPRA'!F24) -> ALUMINIO MACIZO | G19: =IF('ORDEN DE COMPRA'!J24="","",'ORDEN DE COMPRA'!J24) -> 44.5 | H19: =D19*G19 -> 263618 | M19: SALDO EN KILOS DE LA ESCORIA EXPORTACION
C20: ='ORDEN DE COMPRA'!C25 -> 11191610 | D20: =IF('ORDEN DE COMPRA'!D25="","",'ORDEN DE COMPRA'!D25) -> 1830 | E20: =IF('ORDEN DE COMPRA'!E25="","",'ORDEN DE COMPRA'!E25) -> KGM | F20: =IF('ORDEN DE COMPRA'!F25="","",'ORDEN DE COMPRA'!F25) -> ANTIMONIO | G20: =IF('ORDEN DE COMPRA'!J25="","",'ORDEN DE COMPRA'!J25) -> 41 | H20: =D20*G20 -> 75030 | M20: 9197.2
C21: ='ORDEN DE COMPRA'!C26 | D21: =IF('ORDEN DE COMPRA'!D26="","",'ORDEN DE COMPRA'!D26) | E21: =IF('ORDEN DE COMPRA'!E26="","",'ORDEN DE COMPRA'!E26) | F21: =IF('ORDEN DE COMPRA'!F26="","",'ORDEN DE COMPRA'!F26) | G21: =IF('ORDEN DE COMPRA'!J26="","",'ORDEN DE COMPRA'!J26)
C22: ='ORDEN DE COMPRA'!C27 | D22: =IF('ORDEN DE COMPRA'!D27="","",'ORDEN DE COMPRA'!D27) | E22: =IF('ORDEN DE COMPRA'!E27="","",'ORDEN DE COMPRA'!E27) | F22: =IF('ORDEN DE COMPRA'!F27="","",'ORDEN DE COMPRA'!F27) | G22: =IF('ORDEN DE COMPRA'!J27="","",'ORDEN DE COMPRA'!J27) | M22: =M20-D16 -> 1712.2 | N22: FALTARIAN POR CUBRIR
C23: ='ORDEN DE COMPRA'!C28 | D23: =IF('ORDEN DE COMPRA'!D28="","",'ORDEN DE COMPRA'!D28) | E23: =IF('ORDEN DE COMPRA'!E28="","",'ORDEN DE COMPRA'!E28) | F23: =IF('ORDEN DE COMPRA'!F28="","",'ORDEN DE COMPRA'!F28) | G23: =IF('ORDEN DE COMPRA'!J28="","",'ORDEN DE COMPRA'!J28)
C24: ='ORDEN DE COMPRA'!C29 | D24: =IF('ORDEN DE COMPRA'!D29="","",'ORDEN DE COMPRA'!D29) | E24: =IF('ORDEN DE COMPRA'!E29="","",'ORDEN DE COMPRA'!E29) | F24: =IF('ORDEN DE COMPRA'!F29="","",'ORDEN DE COMPRA'!F29) | G24: =IF('ORDEN DE COMPRA'!J29="","",'ORDEN DE COMPRA'!J29)
C25: ='ORDEN DE COMPRA'!C30 | D25: =IF('ORDEN DE COMPRA'!D30="","",'ORDEN DE COMPRA'!D30) | E25: =IF('ORDEN DE COMPRA'!E30="","",'ORDEN DE COMPRA'!E30) | F25: =IF('ORDEN DE COMPRA'!F30="","",'ORDEN DE COMPRA'!F30) | G25: =IF('ORDEN DE COMPRA'!J30="","",'ORDEN DE COMPRA'!J30)
C26: ='ORDEN DE COMPRA'!C31 | D26: =IF('ORDEN DE COMPRA'!D31="","",'ORDEN DE COMPRA'!D31) | E26: =IF('ORDEN DE COMPRA'!E31="","",'ORDEN DE COMPRA'!E31) | F26: =IF('ORDEN DE COMPRA'!F31="","",'ORDEN DE COMPRA'!F31) | G26: =IF('ORDEN DE COMPRA'!J31="","",'ORDEN DE COMPRA'!J31)
C27: ='ORDEN DE COMPRA'!C32 | D27: =IF('ORDEN DE COMPRA'!D32="","",'ORDEN DE COMPRA'!D32) | E27: =IF('ORDEN DE COMPRA'!E32="","",'ORDEN DE COMPRA'!E32) | F27: =IF('ORDEN DE COMPRA'!F32="","",'ORDEN DE COMPRA'!F32) | G27: =IF('ORDEN DE COMPRA'!J32="","",'ORDEN DE COMPRA'!J32)
C28: ='ORDEN DE COMPRA'!C33 | D28: =IF('ORDEN DE COMPRA'!D33="","",'ORDEN DE COMPRA'!D33) | E28: =IF('ORDEN DE COMPRA'!E33="","",'ORDEN DE COMPRA'!E33) | F28: =IF('ORDEN DE COMPRA'!F33="","",'ORDEN DE COMPRA'!F33) | G28: =IF('ORDEN DE COMPRA'!J33="","",'ORDEN DE COMPRA'!J33)
C29: ='ORDEN DE COMPRA'!C34 | D29: =IF('ORDEN DE COMPRA'!D34="","",'ORDEN DE COMPRA'!D34) | E29: =IF('ORDEN DE COMPRA'!E34="","",'ORDEN DE COMPRA'!E34) | F29: =IF('ORDEN DE COMPRA'!F34="","",'ORDEN DE COMPRA'!F34) | G29: =IF('ORDEN DE COMPRA'!J34="","",'ORDEN DE COMPRA'!J34)
C30: TOTAL | D30: =SUM(D16:D28) -> 21560 | H30: =SUM(H16:H27) -> 1105545.5
G33: TOTAL | H33: =H30 -> 1105545.5
C34: IMPORTE EN LETRAS SON:
C35: =Pesos!C4 -> UN MILLON CIENTO CINCO MIL QUINIENTOS CUARENTA Y CINCO PESOS 50/100 M. N.
C38: PAGO: | D38: CONTRA RECEPCIÓN DE DOCUMENTOS
D39: *FACTURA COMERCIAL.
D40: *TICKETS DE PESO
C42: SE TOMARA COMO PESO FINAL EL QUE RESULTE AL MOMENTO QUE EL CLIENTE RECIBA EL MISMO.
C43: RECOLECCIÓN: RECOGIDO EN PLANTA
C44: EL VENDEDOR CORRE CON LOS GASTOS DE MANIOBRA DE CARGA
C45: EL CLIENTE SE REPONSABILIZA DE LA CALIDAD DEL MATERIAL POR LAS CONDICIONES SOLICITADAS

Sheet CONCEPTOS
A1: CONCEPTO | C1: CLAVE SAT | E1: METODOS DE PAGO | G1: FORMAS DE PAGO | I1: EMISOR 2 | J1: RFC | K1: DIRECCION | L1: REGIMEN | N1: RECEPTOR | P1: PROVEEDOR
A2: ACERO 304 | C2: 11191602 | E2: PUE | G2: 01-EFECTIVO | I2: ANDREA SABINA CRUZ VALLEJO | J2: CUVA980829L80 | K2: CALLE 4TA AV No.517 COL. LAGUNA DE LA PUERTA, CP89310, TAMPICO TAMAULIPAS | L2: P.F. ACT EMP Y PROF | N2: ALVARO RESENDIZ GALLEGOS | P2: LUIS BERNAL
A3: ACERO 316 | C3: 11191602 | E3: PPD | G3: 02-CHEQUE NOMINATIVO | I3: COMERCIALIZADORA MEXIPATRIA | J3: CME240220C15 | K3: CALLE COLOMOS No.2604 COL. PRODIVENCIA, CP.44630 GUADALAJARA JALISCO | L3: SIMPLICADO DE CONFIANZA | N3: PERFILES Y ALUMINIOS TAMEX | P3: CESAR DELGADO
A4: ACERO HK | C4: 11191602 | E4: CONTADO | G4: 03-TRANSFERENCIA ELECTRONICA | I4: LIDIA MARICELA UITZ PECH | J4: UIPL770304KV5 | K4: CALLE 18B No.260 COL. ALTABRISA, MERIDA, YUCATAN C.P.97130 | L4: P.F. ACT EMP Y PROF | N4: COLUMBA GUTIERREZ ROJAS | P4: JAVIER VILLARREAL
A5: ALEACION ALUMINIO DELGADO | C5: 11172000 | E5: CREDITO | G5: 04-TARJETA DE CREDITO | I5: ANDREA PAOLA PALOMO CAMARGO | J5: PACA060720JHA | K5: CARR. JOSE CLEMENTE OROZCO No. 842 COL.PRIMERO DE MAYO C.P. 78438, SGS, SAN LUIS POTOSI | L5: P.F. ACT EMP Y PROF | N5: COMERCIALIZADORA MEXIPATRIA | P5: JORGE GONZALEZ
A6: ALEACION ALUMINIO LITOGRAFIA | C6: 11172000 | E6: SI | G6: 05: Monedero electrónico | I6: KARLA DANIELA TORRES BANDA | J6: TOBK030919DR7 | K6: CALLE PINTORES No.607 COL.UNIDAD MODELO, TAMPICO, TAMAULIPAS, C.P.89367 | L6: P.F. ACT EMP Y PROF | N6: ARTURO E. MADRIGAL PORRAS | P6: LUIS GARCIA
A7: ALEACION ALUMINIO TUBO | C7: 11172000 | E7: NO | G7: 06: Dinero electrónico | I7: CESAR MANUEL AVILES DOMINGUEZ | J7: AIDC780612P9A | K7: CALLE 28 No.500D COL.ESPERANZA, MERIDA, YUCATAN C.P.97169 | L7: P.F. ACT EMP Y PROF | N7: ALMA ELENA VELASCO RODRIGUEZ | P7: RODRIGO CALDERA
A8: ALUIMINIO BLANDO | C8: 11191610 | G8: 08: Vales de despensa | I8: ELSY GUADALUPE SOSA CHAVEZ | J8: AIDC780612P9A | K8: CALLE 6 No.370 COL.SAN MARCOS NOCOH, MERIDA, YUCATAN C.P.97296 | L8: P.F. ACT EMP Y PROF | N8: JUANA ISABEL CORONADO RODRIGUEZ | P8: RECICLADOS DIAZ
A9: ALUMINIO 1100 SPRAY | C9: 11191610 | G9: 12: Dación en pago | I9: MARTHA CECILIA MARTINEZ MORALES | J9: MAMM7307199H1 | K9: CALLE BAJA CALIFORNIA No.1 INT.G COL. LOMAS DEL PORVENIR, TIJUANA, B.C. C.P. 22110 | L9: P.F. ACT EMP Y PROF | N9: ANDREA SABINA CRUZ VALLEJO | P9: ALEATONIC
A10: ALUMINIO 1100 TRASTE | C10: 11191610 | G10: 13: Pago por subrogación | I10: MARIA GPE JUAREZ ALVARADO | J10: JUAG970107GYA | K10: CALLE NARANJO No.34 COL. VEGA DEL MAYAB, CONKAL, YUCATAN C.P. 97346 | L10: P.F. ACT EMP Y PROF | N10: ISRAEL ROJAS RIVERO | P10: JOSE ALCANTAR
A11: ALUMINIO BLANDO | C11: 11191610 | G11: 14: Pago por consignación | I11: LUIS FERNANDO ORNELAS FERNANDEZ | J11: OEFL030630F29 | K11: CALLE 135 TABLAJE 23995 INT. B7 COL. CHICHI SUAREZ, MERIDA, YUCATAN C.P. 97306 | L11: P.F. ACT EMP Y PROF | N11: KENNY ISRAEL COLLI CHALE | P11: RECICLADOS PERSA
A12: ALUMINIO BOTE | C12: 11191610 | G12: 15: Condonación | N12: MARIA MAGDALENA GALLEGOS SALAZAR | P12: TOBY
A13: ALUMINIO CABLE | C13: 11191610 | G13: 17: Compensación | N13: CELESTE DE LA CRUZ ROJAS RAMIREZ | P13: RAUL PAZ
A14: ALUMINIO MACIZO | C14: 11191610 | G14: 23: Novación | P14: TANIA
A15: ALUMINIO MACIZO SUCIO | C15: 11191610 | G15: 24: Confusión | P15: PACO MARTINEZ
A16: ALUMINIO PERFIL C/ PINTURA | C16: 11191610 | G16: 25: Remisión de deuda | P16: MTY
A17: ALUMINIO PERIL S/ PINTURA | C17: 11191610 | G17: 26: Prescripción o caducidad | P17: MEINSUR
A18: ALUMINIO RIN CHICO | C18: 11191610 | G18: 27-A SATISFACCION DEL ACREEDOR | I18: EMISOR | J18: RFC | K18: DIRECCION | L18: REGIMEN | P18: ALDREDO AGUILERA
A19: ALUMINIO RIN GRANDE | C19: 11191610 | G19: 28-TARJETA DE DEBITO | I19: ALVARO RESENDIZ GALLEGOS | J19: REGA5602198E6 | K19: CALLE 22 No109A ENTRE 23 Y 25 CHOLUL, MERIDA, YUCATAN, MEXICO | L19: P.F. ACT EMP Y PROF | P19: ANGEL FLORES
A20: ALUMINIO SUCIO | C20: 11191610 | G20: 29-TARJETA DE SERVICIOS | I20: HECTOR RESENDIZ GALLEGOS | J20: REGH680904C68 | K20: CALLE 135 TABLAJE 23995 INT. B7 COL. CHICHI SUAREZ, MERIDA, YUCATAN C.P. 97306 | L20: P.F. ACT EMP Y PROF | P20: SERVIN
A21: FOIL | C21: 11191610 | G21: 30-APLICACIÓN DE ANTICIPO | I21: NEGOCIOS LOGISTICOS DEL GOLFO | J21: NLG2302151IA | K21: CALLE 20 No.100 CP. 97305 ENTRE 23 Y 25 COL. CHOLUL, MERIDA, YUCATAN | L21: P.M. REGIMEN GENERAL | P21: MARIELENA MENDEZ
A22: ALUMINIO TUBO | C22: 11191610 | G22: 99-POR DEFINIR | P22: RECMAT
A23: ANTIMONIO | C23: 11191610 | P23: BRYAN CERVANTES
A24: BRONCE AMARILLO LIMPIO | C24: 11191600
A25: BRONCE AMARILLO SUCIO | C25: 11191600
A26: BRONCE LATON 75/25 | C26: 11191600
A27: BRONCE MANGANESO | C27: 11191600
A28: BRONCE REBABA MIXTA AMARILLO | C28: 11191600
A29: BRONCE ROJO | C29: 11191600
A30: COBRE BRILLOSO | C30: 11191607
A31: COBRE BRILLOSO 1 | C31: 11191607
A32: COBRE CANDY PLACA | C32: 11191607
A33: COBRE CANDY TUBO | C33: 11191607
A34: COBRE CANDY TUBO Y PLACA | C34: 11191607
A35: COBRE ESTAÑADO | C35: 11191607
... A52: ALUM 5000 POLI | C52: 11191610

Sheet Pesos
C2: RESULTADO
C3: ='ORDEN DE COMPRA'!H38 -> 1105545.5
C4: =(C13&" "&D13&" "&E13&" "&E14&" "&F13&" "&D14&" "&G13&" "&G14&" "&H13&" "&H14&" "&H15&" "&I13&" "&D15&" "&J12&"/100 M. N.") -> UN MILLON CIENTO CINCO MIL QUINIENTOS CUARENTA Y CINCO PESOS 50/100 M. N.
C5: =TRIM(C4) -> UN MILLON CIENTO CINCO MIL QUINIENTOS CUARENTA Y CINCO PESOS 50/100 M. N.
D7: CENTENA | E7: DECENA | F7: UNIDAD | J7: CENTAVOS
C8: MILLONES | D8: DE MILLAR | E8: DE MILLAR | F8: DE MILLAR | G8: CENTENAS | H8: DECENAS | I8: UNIDADES
D9: =C3-C11*1000000 -> 105545.5 | E9: =D9-D11*100000 -> 5545.5038 | F9: =E9-E11*10000 -> 5545.5038 | G9: =F9-F11*1000 -> 545.50383 | H9: =G9-G11*100 -> 45.503828 | I9: =H9-H11*10 -> 5.5038277 | J9: =I9-I11*1 -> 0.50382772
C10: =$C$3/1000000 -> 1.1055455 | D10: =D9/100000 -> 1.055455 | E10: =E9/10000 -> 0.55455038 | F10: =F9/1000 -> 5.5455038 | G10: =G9/100 -> 5.4550383 | H10: =H9/10 -> 4.5503828 | I10: =I9/1 -> 5.5038277 | J10: =J9*100 -> 50.382772
C11: =INT(C10) -> 1 | D11: =INT(D10) -> 1 | E11: =INT(E10) -> 0 | F11: =INT(F10) -> 5 | G11: =INT(G10) -> 5 | H11: =INT(H10) -> 4 | I11: =INT(I10) -> 5 | J11: =IF(J10=0,"00",ROUND(J10,0)) -> 50
H12: =IF(AND(H9>10,H11<20),INT(H9),0) -> 45 | J12: =IF(J11<10,("0"&J11),J11) -> 50
C13: =IF(C11=0,"",VLOOKUP(C11,MASTERTABLE,2)) -> UN MILLON | D13: =IF(D11=0,"",IF(AND(D11=1,E11=0,F11=0),"CIEN",VLOOKUP(D11,MASTERTABLE,3))) -> CIENTO | E13: =IF(E11=0,"",IF(AND(E9>10999,E9<30000),VLOOKUP(E15,auxtable,2),VLOOKUP(E11,MASTERTABLE,4))) | F13: =IF(F11=0," ",IF(AND(E9>10999,E9<30000)," ",VLOOKUP(F11,MASTERTABLE,5))) -> CINCO | G13: =IF(OR(G11=0,C3=100)," ",VLOOKUP(G11,MASTERTABLE,6)) -> QUINIENTOS | H13: =IF(H11=0," ",IF(AND(H9>10,H9<30),VLOOKUP(H12,auxtable,2),VLOOKUP(H11,MASTERTABLE,7))) -> CUARENTA | I13: =IF(I11=0," ",IF(AND(H9>10,H9<30)," ",VLOOKUP(I11,MASTERTABLE,8))) -> CINCO
D14: =IF(F11=1,"MIL",IF(AND(D11=0,E11=0,F11=0),"","MIL")) -> MIL | E14: =IF(AND(E15>30,E11<>0,I11<>0),"Y","") | G14: =IF(C3=100,"CIEN","") | H14: =IF(AND(H12>30,H11<>0,I11<>0),"Y","") -> Y | I14: =IF(AND(H9>9,H9<30),"",(IF(AND(G11<>0,H11<>0),"Y",""))) -> Y
D15: =IF(C3=1,"PESO",(IF(AND(C11<>0,D11=0,E11=0,F11=0),"DE PESOS","PESOS"))) -> PESOS | E15: =IF(H9>20000,0,INT(E9/1000)) -> 5 | I15: =IF(AND(H12>30,H11<>0,I11<>0),"Y","") -> Y
B17: 1 | C17: UN MILLON | D17: CIENTO | E17: DIEZ | F17: UN | G17: CIENTO | H17: DIEZ | I17: UN | L17: 10 | M17: DIEZ
B18: =+B17+1 -> 2 | C18: DOS MILLONES | D18: DOSCIENTOS | E18: VEINTE | F18: DOS | G18: DOSCIENTOS | H18: VEINTE | I18: DOS | L18: 11 | M18: ONCE
B19: =+B18+1 -> 3 | C19: TRES MILLONES | D19: TRESCIENTOS | E19: TREINTA | F19: TRES | G19: TRESCIENTOS | H19: TREINTA | I19: TRES | L19: 12 | M19: DOCE
B20: =+B19+1 -> 4 | C20: CUATRO MILLONES | D20: CUATROCIENTOS | E20: CUARENTA | F20: CUATRO | G20: CUATROCIENTOS | H20: CUARENTA | I20: CUATRO | L20: 13 | M20: TRECE
B21: =+B20+1 -> 5 | C21: CINCO MILLONES | D21: QUINIENTOS | E21: CINCUENTA | F21: CINCO | G21: QUINIENTOS | H21: CINCUENTA | I21: CINCO | L21: 14 | M21: CATORCE
B22: =+B21+1 -> 6 | C22: SEIS MILLONES | D22: SEISCIENTOS | E22: SESENTA | F22: SEIS | G22: SEISCIENTOS | H22: SESENTA | I22: SEIS | L22: 15 | M22: QUINCE
B23: =+B22+1 -> 7 | C23: SIETE MILLONES | D23: SETECIENTOS | E23: SETENTA | F23: SIETE | G23: SETECIENTOS | H23: SETENTA | I23: SIETE | L23: 16 | M23: DIECISEIS
B24: =+B23+1 -> 8 | C24: OCHO MILLONES | D24: OCHOCIENTOS | E24: OCHENTA | F24: OCHO | G24: OCHOCIENTOS | H24: OCHENTA | I24: OCHO | L24: 17 | M24: DIECISIETE
B25: =+B24+1 -> 9 | C25: NUEVE MILLONES | D25: NOVECIENTOS | E25: NOVENTA | F25: NUEVE | G25: NOVECIENTOS | H25: NOVENTA | I25: NUEVE | L25: 18 | M25: DIECIOCHO
B26: =+B25+1 -> 10 | C26: DIEZ MILLONES | L26: 19 | M26: DIECINUEVE
B27: =+B26+1 -> 11 | C27: ONCE MILLONES | L27: 20 | M27: VEINTE
B28: =+B27+1 -> 12 | C28: DOCE MILLONES | L28: 21 | M28: VEINTIUN
B29: =+B28+1 -> 13 | C29: TRECE MILLONES | L29: 22 | M29: VEINTIDOS
B30: =+B29+1 -> 14 | C30: CATORCE MILLONES | L30: 23 | M30: VEINTITRES
B31: =+B30+1 -> 15 | C31: QUINCE MILLONES | L31: 24 | M31: VEINTICUATRO
B32: =+B31+1 -> 16 | L32: 25 | M32: VEINTICINCO
B33: =+B32+1 -> 17 | L33: 26 | M33: VEINTISEIS
B34: =+B33+1 -> 18 | L34: 27 | M34: VEINTISIETE
B35: =+B34+1 -> 19 | L35: 28 | M35: VEINTIOCHO
B36: =+B35+1 -> 20 | L36: 29 | M36: VEINTINUEVE
B37: =+B36+1 -> 21
B38: =+B37+1 -> 22
B39: =+B38+1 -> 23
B40: =+B39+1 -> 24
